[2024-04-16T04:20:57.427+0000] {taskinstance.py:1165} INFO - Dependencies all met for <TaskInstance: first_dag.clean_data scheduled__2024-01-11T00:00:00+00:00 [queued]>
[2024-04-16T04:20:57.437+0000] {taskinstance.py:1165} INFO - Dependencies all met for <TaskInstance: first_dag.clean_data scheduled__2024-01-11T00:00:00+00:00 [queued]>
[2024-04-16T04:20:57.438+0000] {taskinstance.py:1362} INFO - 
--------------------------------------------------------------------------------
[2024-04-16T04:20:57.438+0000] {taskinstance.py:1363} INFO - Starting attempt 2 of 2
[2024-04-16T04:20:57.438+0000] {taskinstance.py:1364} INFO - 
--------------------------------------------------------------------------------
[2024-04-16T04:20:57.451+0000] {taskinstance.py:1383} INFO - Executing <Task(_PythonDecoratedOperator): clean_data> on 2024-01-11 00:00:00+00:00
[2024-04-16T04:20:57.456+0000] {standard_task_runner.py:55} INFO - Started process 448 to run task
[2024-04-16T04:20:57.458+0000] {standard_task_runner.py:82} INFO - Running: ['***', 'tasks', 'run', 'first_dag', 'clean_data', 'scheduled__2024-01-11T00:00:00+00:00', '--job-id', '1080', '--raw', '--subdir', 'DAGS_FOLDER/FirstDag.py', '--cfg-path', '/tmp/tmpvd6jvc6t']
[2024-04-16T04:20:57.459+0000] {standard_task_runner.py:83} INFO - Job 1080: Subtask clean_data
[2024-04-16T04:20:57.525+0000] {task_command.py:376} INFO - Running <TaskInstance: first_dag.clean_data scheduled__2024-01-11T00:00:00+00:00 [running]> on host b0ce51d36eb8
[2024-04-16T04:20:57.606+0000] {taskinstance.py:1592} INFO - Exporting the following env vars:
AIRFLOW_CTX_DAG_OWNER=***
AIRFLOW_CTX_DAG_ID=first_dag
AIRFLOW_CTX_TASK_ID=clean_data
AIRFLOW_CTX_EXECUTION_DATE=2024-01-11T00:00:00+00:00
AIRFLOW_CTX_TRY_NUMBER=2
AIRFLOW_CTX_DAG_RUN_ID=scheduled__2024-01-11T00:00:00+00:00
[2024-04-16T04:20:57.609+0000] {taskinstance.py:1851} ERROR - Task failed with exception
Traceback (most recent call last):
  File "/home/airflow/.local/lib/python3.7/site-packages/airflow/decorators/base.py", line 188, in execute
    return_value = super().execute(context)
  File "/home/airflow/.local/lib/python3.7/site-packages/airflow/operators/python.py", line 175, in execute
    return_value = self.execute_callable()
  File "/home/airflow/.local/lib/python3.7/site-packages/airflow/operators/python.py", line 193, in execute_callable
    return self.python_callable(*self.op_args, **self.op_kwargs)
  File "/opt/airflow/dags/FirstDag.py", line 44, in clean_data
    existing_data = json.load(f)
  File "/usr/local/lib/python3.7/json/__init__.py", line 296, in load
    parse_constant=parse_constant, object_pairs_hook=object_pairs_hook, **kw)
  File "/usr/local/lib/python3.7/json/__init__.py", line 348, in loads
    return _default_decoder.decode(s)
  File "/usr/local/lib/python3.7/json/decoder.py", line 337, in decode
    obj, end = self.raw_decode(s, idx=_w(s, 0).end())
  File "/usr/local/lib/python3.7/json/decoder.py", line 355, in raw_decode
    raise JSONDecodeError("Expecting value", s, err.value) from None
json.decoder.JSONDecodeError: Expecting value: line 1 column 1 (char 0)
[2024-04-16T04:20:57.620+0000] {taskinstance.py:1406} INFO - Marking task as FAILED. dag_id=first_dag, task_id=clean_data, execution_date=20240111T000000, start_date=20240416T042057, end_date=20240416T042057
[2024-04-16T04:20:57.632+0000] {standard_task_runner.py:105} ERROR - Failed to execute job 1080 for task clean_data (Expecting value: line 1 column 1 (char 0); 448)
[2024-04-16T04:20:57.671+0000] {local_task_job.py:164} INFO - Task exited with return code 1
[2024-04-16T04:20:57.697+0000] {local_task_job.py:273} INFO - 0 downstream tasks scheduled from follow-on schedule check
